Workbook

Sheet Executive Summary
B2: Pfizer Inc. (PFE) — Executive Summary
B3: Financial Model & Valuation Overview | March 2026
B5: COMPANY OVERVIEW
B6: Sector | C6: Healthcare / Biopharma
B7: Market Cap ($B) | C7: 152.4
B8: Enterprise Value ($B) | C8: 196.8
B9: Current Price | C9: 26.6
B10: Shares Outstanding (B) | C10: 5.7
B11: Credit Rating | C11: A / A2 (Stable)
B12: Dividend Yield | C12: 0.063
B14: KEY FINANCIAL METRICS
C15: FY2024 | D15: FY2025E | E15: FY2026E | F15: FY2027E
B16: Revenue ($M) | C16: ='Income Statement'!F7 -> 63627 | D16: ='Income Statement'!G7 -> 62600 | E16: ='Income Statement'!H7 -> 61800 | F16: ='Income Statement'!I7 -> 62400
B17: EBITDA ($M) | C17: ='Income Statement'!F14 -> 20224 | D17: ='Income Statement'!G14 -> 20971 | E17: ='Income Statement'!H14 -> 21630 | F17: ='Income Statement'!I14 -> 22776
B18: EBITDA Margin | C18: ='Income Statement'!F15 -> 0.31785248 | D18: ='Income Statement'!G15 -> 0.335 | E18: ='Income Statement'!H15 -> 0.35 | F18: ='Income Statement'!I15 -> 0.365
B19: Net Income ($M) | C19: ='Income Statement'!F25 -> 3164.608 | D19: ='Income Statement'!G25 -> 6369.1779 | E19: ='Income Statement'!H25 -> 7603.9729 | F19: ='Income Statement'!I25 -> 8979.1454
B20: Diluted EPS | C20: ='Income Statement'!F28 -> 1.41 | D20: ='Income Statement'!G28 -> 1.1173996 | E20: ='Income Statement'!H28 -> 1.3340303 | F20: ='Income Statement'!I28 -> 1.5752887
B22: VALUATION SUMMARY
B23: Methodology | C23: Implied Price | D23: Upside/(Downside)
B24: DCF (Base Case) | C24: =DCF!C38 -> 59.887863 | D24: =DCF!C40 -> 1.2514234
B25: EV/EBITDA Comps (Median) | C25: =Comps!C22 -> 52.986842 | D25: =C25/C9-1 -> 0.99198655
B26: P/E Comps (Median NTM) | C26: =Comps!C24 -> 20.655132 | D26: =C26/C9-1 -> -0.22349127
B28: KEY RISKS & CONSIDERATIONS
B29: • Loss of exclusivity (LOE): >$6B revenue at risk by 2028 from patent expirations
B30: • COVID-19 revenue normalization: Comirnaty/Paxlovid demand declining from FY2022 peak
B31: • Seagen integration: $43B acquisition must deliver on oncology pipeline synergies
B32: • High debt load: $60B+ total debt constrains financial flexibility
B33: • Pipeline risk: Heavy dependence on oncology pipeline success (Padcev, Adcetris, etc.)
B34: • Pricing pressure: IRA drug pricing negotiation impact beginning 2026+
B36: KEY CATALYSTS
B37: • Seagen oncology portfolio ramp (Padcev + Adcetris >$5B potential)
B38: • Debt deleveraging: $3-4B annual mandatory repayments improving balance sheet
B39: • Obesity/metabolic pipeline optionality (danuglipron oral GLP-1)
B40: • Cost restructuring program targeting >$4B in savings by 2027

Sheet Assumptions
B2: Pfizer Inc. — Model Assumptions & Drivers
B3: ($ in millions unless noted)
C4: Historical | G4: Projected
C5: FY2021 | D5: FY2022 | E5: FY2023 | F5: FY2024 | G5: FY2025E | H5: FY2026E | I5: FY2027E | J5: FY2028E | K5: FY2029E
B7: REVENUE DRIVERS
B8: Total Revenue | C8: 81288 | D8: 100330 | E8: 59553 | F8: 63627 | G8: 62600 | H8: 61800 | I8: 62400 | J8: 64900 | K8: 68100
B9: Revenue Growth % | C9: 0.93967739 | D9: =D8/C8-1 -> 0.23425352 | E9: =E8/D8-1 -> -0.40642879 | F9: =F8/E8-1 -> 0.068409652 | G9: =G8/F8-1 -> -0.016140946 | H9: =H8/G8-1 -> -0.012779553 | I9: =I8/H8-1 -> 0.0097087379 | J9: =J8/I8-1 -> 0.040064103 | K9: =K8/J8-1 -> 0.049306626
B11: MARGIN DRIVERS
B12: COGS % of Revenue | C12: 0.375 | D12: 0.342 | E12: 0.419 | F12: 0.281 | G12: 0.28 | H12: 0.275 | I12: 0.27 | J12: 0.265 | K12: 0.26
B13: SI&A % of Revenue | C13: 0.156 | D13: 0.135 | E13: 0.226 | F13: 0.232 | G13: 0.22 | H13: 0.215 | I13: 0.21 | J13: 0.205 | K13: 0.2
B14: R&D % of Revenue | C14: 0.127 | D14: 0.114 | E14: 0.195 | F14: 0.17 | G14: 0.165 | H14: 0.16 | I14: 0.155 | J14: 0.15 | K14: 0.148
B15: Implied Gross Margin | C15: =1-C12 -> 0.625 | D15: =1-D12 -> 0.658 | E15: =1-E12 -> 0.581 | F15: =1-F12 -> 0.719 | G15: =1-G12 -> 0.72 | H15: =1-H12 -> 0.725 | I15: =1-I12 -> 0.73 | J15: =1-J12 -> 0.735 | K15: =1-K12 -> 0.74
B16: Implied EBITDA Margin | C16: =C15-C13-C14 -> 0.342 | D16: =D15-D13-D14 -> 0.409 | E16: =E15-E13-E14 -> 0.16 | F16: =F15-F13-F14 -> 0.317 | G16: =G15-G13-G14 -> 0.335 | H16: =H15-H13-H14 -> 0.35 | I16: =I15-I13-I14 -> 0.365 | J16: =J15-J13-J14 -> 0.38 | K16: =K15-K13-K14 -> 0.392
B18: OTHER IS DRIVERS
B19: Amortization of Intangibles | C19: 3700 | D19: 3609 | E19: 4751 | F19: 5286 | G19: 5000 | H19: 4800 | I19: 4600 | J19: 4400 | K19: 4200
B20: Restructuring & Other | C20: 417 | D20: 486 | E20: 3610 | F20: 2419 | G20: 1500 | H20: 1000 | I20: 750 | J20: 500 | K20: 300
B21: Other (Income)/Deductions | C21: 1437 | D21: 2059 | E21: -3225 | F21: 4388 | G21: 2500 | H21: 2500 | I21: 2500 | J21: 2500 | K21: 2500
B22: Effective Tax Rate | C22: 0.063 | D22: 0.085 | E22: -0.484 | F22: -0.004 | G22: 0.15 | H22: 0.15 | I22: 0.15 | J22: 0.15 | K22: 0.15
B24: BALANCE SHEET DRIVERS
B25: Days Sales Outstanding (DSO) | C25: 52 | D25: 40 | E25: 71 | F25: 66 | G25: 65 | H25: 65 | I25: 65 | J25: 65 | K25: 65
B26: Days Inventory Outstanding (DIO) | C26: 108 | D26: 95 | E26: 149 | F26: 222 | G26: 180 | H26: 170 | I26: 160 | J26: 155 | K26: 150
B27: Days Payable Outstanding (DPO) | C27: 82 | D27: 59 | E27: 82 | F27: 115 | G27: 100 | H27: 100 | I27: 100 | J27: 100 | K27: 100
B28: Other Current Assets % Rev | C28: 0.057 | D28: 0.061 | E28: 0.105 | F28: 0.119 | G28: 0.1 | H28: 0.095 | I28: 0.09 | J28: 0.088 | K28: 0.085
B29: Accrued Liabilities % Rev | C29: 0.242 | D29: 0.203 | E29: 0.475 | F29: 0.478 | G29: 0.45 | H29: 0.43 | I29: 0.41 | J29: 0.4 | K29: 0.39
B31: CAPEX & D&A
B32: CapEx % of Revenue | C32: 0.033 | D32: 0.032 | E32: 0.066 | F32: 0.046 | G32: 0.045 | H32: 0.043 | I32: 0.042 | J32: 0.04 | K32: 0.038
B33: Depreciation (est.) | C33: 1491 | D33: 1455 | E33: 1539 | F33: 1727 | G33: 1800 | H33: 1850 | I33: 1900 | J33: 1950 | K33: 2000
B35: CAPITAL STRUCTURE
B36: Dividends per Share ($) | C36: 1.56 | D36: 1.64 | E36: 1.64 | F36: 1.68 | G36: 1.68 | H36: 1.72 | I36: 1.76 | J36: 1.8 | K36: 1.84
B37: Diluted Shares (M) | C37: 5708 | D37: 5733 | E37: 5709 | F37: 5700 | G37: 5700 | H37: 5700 | I37: 5700 | J37: 5700 | K37: 5700
B38: Share Repurchases | C38: 2114 | D38: 3283 | E38: 2000 | F38: 0 | G38: 0 | H38: 0 | I38: 0 | J38: 0 | K38: 0
B40: WACC INPUTS
B41: Risk-Free Rate | C41: 0.0415
B42: Equity Risk Premium | C42: 0.0423
B43: Levered Beta | C43: 0.41
B44: Pre-tax Cost of Debt | C44: 0.0479
B45: Market Cap ($B) | C45: 152.4
B46: Total Debt ($B) | C46: 60.8
B47: Marginal Tax Rate | C47: 0.15
B48: Terminal Growth Rate | C48: 0.02
...

Sheet Income Statement
B2: Pfizer Inc. — Income Statement
B3: ($ in millions, except per share data)
C4: Historical | G4: Projected
C5: FY2021 | D5: FY2022 | E5: FY2023 | F5: FY2024 | G5: FY2025E | H5: FY2026E | I5: FY2027E | J5: FY2028E | K5: FY2029E
B6: REVENUE
B7: Total Revenue | C7: 81288 | D7: 100330 | E7: 59553 | F7: 63627 | G7: =Assumptions!G8 -> 62600 | H7: =Assumptions!H8 -> 61800 | I7: =Assumptions!I8 -> 62400 | J7: =Assumptions!J8 -> 64900 | K7: =Assumptions!K8 -> 68100
B8: Cost of Sales | C8: -30483 | D8: -34344 | E8: -24954 | F8: -17851 | G8: =-G7*Assumptions!G12 -> -17528 | H8: =-H7*Assumptions!H12 -> -16995 | I8: =-I7*Assumptions!I12 -> -16848 | J8: =-J7*Assumptions!J12 -> -17198.5 | K8: =-K7*Assumptions!K12 -> -17706
B9: Gross Profit | C9: =C7+C8 -> 50805 | D9: =D7+D8 -> 65986 | E9: =E7+E8 -> 34599 | F9: =F7+F8 -> 45776 | G9: =G7+G8 -> 45072 | H9: =H7+H8 -> 44805 | I9: =I7+I8 -> 45552 | J9: =J7+J8 -> 47701.5 | K9: =K7+K8 -> 50394
B10: Gross Margin % | C10: =C9/C7 -> 0.625 | D10: =D9/D7 -> 0.65768962 | E10: =E9/E7 -> 0.58097829 | F10: =F9/F7 -> 0.719443 | G10: =G9/G7 -> 0.72 | H10: =H9/H7 -> 0.725 | I10: =I9/I7 -> 0.73 | J10: =J9/J7 -> 0.735 | K10: =K9/K7 -> 0.74
B11: OPERATING EXPENSES
B12: SI&A Expense | C12: -12703 | D12: -13554 | E12: -13476 | F12: -14730 | G12: =-G7*Assumptions!G13 -> -13772 | H12: =-H7*Assumptions!H13 -> -13287 | I12: =-I7*Assumptions!I13 -> -13104 | J12: =-J7*Assumptions!J13 -> -13304.5 | K12: =-K7*Assumptions!K13 -> -13620
B13: R&D Expense | C13: -10361 | D13: -11428 | E13: -11603 | F13: -10822 | G13: =-G7*Assumptions!G14 -> -10329 | H13: =-H7*Assumptions!H14 -> -9888 | I13: =-I7*Assumptions!I14 -> -9672 | J13: =-J7*Assumptions!J14 -> -9735 | K13: =-K7*Assumptions!K14 -> -10078.8
B14: EBITDA | C14: =C9+C12+C13 -> 27741 | D14: =D9+D12+D13 -> 41004 | E14: =E9+E12+E13 -> 9520 | F14: =F9+F12+F13 -> 20224 | G14: =G9+G12+G13 -> 20971 | H14: =H9+H12+H13 -> 21630 | I14: =I9+I12+I13 -> 22776 | J14: =J9+J12+J13 -> 24662 | K14: =K9+K12+K13 -> 26695.2
B15: EBITDA Margin % | C15: =C14/C7 -> 0.34126808 | D15: =D14/D7 -> 0.40869132 | E15: =E14/E7 -> 0.15985761 | F15: =F14/F7 -> 0.31785248 | G15: =G14/G7 -> 0.335 | H15: =H14/H7 -> 0.35 | I15: =I14/I7 -> 0.365 | J15: =J14/J7 -> 0.38 | K15: =K14/K7 -> 0.392
B16: NON-CASH & OTHER ITEMS
B17: Amortization of Intangibles | C17: -3700 | D17: -3609 | E17: -4751 | F17: -5286 | G17: =-Assumptions!G19 -> -5000 | H17: =-Assumptions!H19 -> -4800 | I17: =-Assumptions!I19 -> -4600 | J17: =-Assumptions!J19 -> -4400 | K17: =-Assumptions!K19 -> -4200
B18: Depreciation | C18: -1491 | D18: -1455 | E18: -1539 | F18: -1727 | G18: =-Assumptions!G33 -> -1800 | H18: =-Assumptions!H33 -> -1850 | I18: =-Assumptions!I33 -> -1900 | J18: =-Assumptions!J33 -> -1950 | K18: =-Assumptions!K33 -> -2000
B19: Restructuring & Other | C19: -417 | D19: -486 | E19: -3610 | F19: -2419 | G19: =-Assumptions!G20 -> -1500 | H19: =-Assumptions!H20 -> -1000 | I19: =-Assumptions!I20 -> -750 | J19: =-Assumptions!J20 -> -500 | K19: =-Assumptions!K20 -> -300
B20: Other (Income)/Deductions | C20: -1437 | D20: -2059 | E20: 3225 | F20: -4388 | G20: =-Assumptions!G21 -> -2500 | H20: =-Assumptions!H21 -> -2500 | I20: =-Assumptions!I21 -> -2500 | J20: =-Assumptions!J21 -> -2500 | K20: =-Assumptions!K21 -> -2500
B21: EBIT | C21: =C14+C17+C18+C19+C20 -> 20696 | D21: =D14+D17+D18+D19+D20 -> 33395 | E21: =E14+E17+E18+E19+E20 -> 2845 | F21: =F14+F17+F18+F19+F20 -> 6404 | G21: =G14+G17+G18+G19+G20 -> 10171 | H21: =H14+H17+H18+H19+H20 -> 11480 | I21: =I14+I17+I18+I19+I20 -> 13026 | J21: =J14+J17+J18+J19+J20 -> 15312 | K21: =K14+K17+K18+K19+K20 -> 17695.2
B22: Interest Expense (from Debt Sched.) | C22: -1398 | D22: -1399 | E22: -3385 | F22: -3252 | G22: ='Debt Schedule'!G14 -> -2677.8495 | H22: ='Debt Schedule'!H14 -> -2534.1495 | I22: ='Debt Schedule'!I14 -> -2462.2995 | J22: ='Debt Schedule'!J14 -> -2366.4995 | K22: ='Debt Schedule'!K14 -> -2270.6995
B23: Income Before Tax | C23: =C21+C22 -> 19298 | D23: =D21+D22 -> 31996 | E23: =E21+E22 -> -540 | F23: =F21+F22 -> 3152 | G23: =G21+G22 -> 7493.1505 | H23: =H21+H22 -> 8945.8505 | I23: =I21+I22 -> 10563.7 | J23: =J21+J22 -> 12945.501 | K23: =K21+K22 -> 15424.501
B24: Income Tax Expense | C24: =-C23*0.063 -> -1215.774 | D24: =-D23*0.085 -> -2719.66 | E24: =-E23*-0.484 -> -261.36 | F24: =-F23*-0.004 -> 12.608 | G24: =-G23*Assumptions!G22 -> -1123.9726 | H24: =-H23*Assumptions!H22 -> -1341.8776 | I24: =-I23*Assumptions!I22 -> -1584.5551 | J24: =-J23*Assumptions!J22 -> -1941.8251 | K24: =-K23*Assumptions!K22 -> -2313.6751
B25: Net Income | C25: =C23+C24 -> 18082.226 | D25: =D23+D24 -> 29276.34 | E25: =E23+E24 -> -801.36 | F25: =F23+F24 -> 3164.608 | G25: =G23+G24 -> 6369.1779 | H25: =H23+H24 -> 7603.9729 | I25: =I23+I24 -> 8979.1454 | J25: =J23+J24 -> 11003.675 | K25: =K23+K24 -> 13110.825
B26: PER SHARE DATA
B27: Diluted Shares (M) | C27: 5708 | D27: 5733 | E27: 5709 | F27: 5700 | G27: =Assumptions!G37 -> 5700 | H27: =Assumptions!H37 -> 5700 | I27: =Assumptions!I37 -> 5700 | J27: =Assumptions!J37 -> 5700 | K27: =Assumptions!K37 -> 5700
B28: Diluted EPS | C28: 3.85 | D28: 5.47 | E28: 0.37 | F28: 1.41 | G28: =G25/G27 -> 1.1173996 | H28: =H25/H27 -> 1.3340303 | I28: =I25/I27 -> 1.5752887 | J28: =J25/J27 -> 1.9304694 | K28: =K25/K27 -> 2.3001448
B29: Dividends per Share | C29: 1.56 | D29: 1.64 | E29: 1.64 | F29: 1.68 | G29: =Assumptions!G36 -> 1.68 | H29: =Assumptions!H36 -> 1.72 | I29: =Assumptions!I36 -> 1.76 | J29: =Assumptions!J36 -> 1.8 | K29: =Assumptions!K36 -> 1.84

Sheet Balance Sheet
B2: Pfizer Inc. — Balance Sheet
B3: ($ in millions)
C5: FY2021 | D5: FY2022 | E5: FY2023 | F5: FY2024 | G5: FY2025E | H5: FY2026E | I5: FY2027E | J5: FY2028E | K5: FY2029E
B6: CURRENT ASSETS
B7: Cash & Short-term Investments | C7: 31069 | D7: 22732 | E7: 12690 | F7: 20477 | G7: ='Cash Flow Statement'!G28 -> 5282.4793 | H7: ='Cash Flow Statement'!H28 -> 4492.9563 | I7: ='Cash Flow Statement'!I28 -> 7867.2333 | J7: ='Cash Flow Statement'!J28 -> 9278.4827 | K7: ='Cash Flow Statement'!K28 -> 16531.42
B8: Accounts Receivable | C8: 11479 | D8: 10952 | E8: 11566 | F8: 11463 | G8: ='Working Capital'!G18 -> 11147.945 | H8: ='Working Capital'!H18 -> 11005.479 | I8: ='Working Capital'!I18 -> 11112.329 | J8: ='Working Capital'!J18 -> 11557.534 | K8: ='Working Capital'!K18 -> 12127.397
B9: Inventories | C9: 9059 | D9: 8981 | E9: 10189 | F9: 10851 | G9: ='Working Capital'!G19 -> 8643.9452 | H9: ='Working Capital'!H19 -> 7915.4795 | I9: ='Working Capital'!I19 -> 7385.4247 | J9: ='Working Capital'!J19 -> 7303.4726 | K9: ='Working Capital'!K19 -> 7276.4384
B10: Other Current Assets | C10: 4654 | D10: 6099 | E10: 6270 | F10: 7567 | G10: ='Working Capital'!G20 -> 6260 | H10: ='Working Capital'!H20 -> 5871 | I10: ='Working Capital'!I20 -> 5616 | J10: ='Working Capital'!J20 -> 5711.2 | K10: ='Working Capital'!K20 -> 5788.5
B11: Total Current Assets | C11: =SUM(C7:C10) -> 56261 | D11: =SUM(D7:D10) -> 48764 | E11: =SUM(E7:E10) -> 40715 | F11: =SUM(F7:F10) -> 50358 | G11: =SUM(G7:G10) -> 31334.37 | H11: =SUM(H7:H10) -> 29284.915 | I11: =SUM(I7:I10) -> 31980.987 | J11: =SUM(J7:J10) -> 33850.69 | K11: =SUM(K7:K10) -> 41723.756
B12: NON-CURRENT ASSETS
B13: PP&E, net | C13: 13508 | D13: 14177 | E13: 17693 | F13: 18393 | G13: =F13+'Income Statement'!G7*Assumptions!G32-Assumptions!G33 -> 19410 | H13: =G13+'Income Statement'!H7*Assumptions!H32-Assumptions!H33 -> 20217.4 | I13: =H13+'Income Statement'!I7*Assumptions!I32-Assumptions!I33 -> 20938.2 | J13: =I13+'Income Statement'!J7*Assumptions!J32-Assumptions!J33 -> 21584.2 | K13: =J13+'Income Statement'!K7*Assumptions!K32-Assumptions!K33 -> 22172
B14: Goodwill | C14: 49199 | D14: 49180 | E14: 67782 | F14: 68527 | G14: =F14 -> 68527 | H14: =G14 -> 68527 | I14: =H14 -> 68527 | J14: =I14 -> 68527 | K14: =J14 -> 68527
B15: Intangible Assets, net | C15: 23710 | D15: 30455 | E15: 63979 | F15: 55411 | G15: =F15-Assumptions!G19 -> 50411 | H15: =G15-Assumptions!H19 -> 45611 | I15: =H15-Assumptions!I19 -> 41011 | J15: =I15-Assumptions!J19 -> 36611 | K15: =J15-Assumptions!K19 -> 32411
B16: Other Non-current Assets | C16: =181475-C11-C13-C14-C15 -> 38797 | D16: =197204-D11-D13-D14-D15 -> 54628 | E16: =226501-E11-E13-E14-E15 -> 36332 | F16: =213396-F11-F13-F14-F15 -> 20707 | G16: =G17-G11-G13-G14-G15 -> 27484 | H16: =H17-H11-H13-H14-H15 -> 26584 | I16: =I17-I11-I13-I14-I15 -> 25684 | J16: =J17-J11-J13-J14-J15 -> 24784 | K16: =K17-K11-K13-K14-K15 -> 23884
B17: Total Assets | C17: =C11+C13+C14+C15+C16 -> 181475 | D17: =D11+D13+D14+D15+D16 -> 197204 | E17: =E11+E13+E14+E15+E16 -> 226501 | F17: =F11+F13+F14+F15+F16 -> 213396 | G17: =G28 -> 197166.37 | H17: =H28 -> 190224.32 | I17: =I28 -> 188141.19 | J17: =J28 -> 185356.89 | K17: =K28 -> 188717.76
B18: LIABILITIES
B19: Short-term Debt | C19: 2241 | D19: 2945 | E19: 10350 | F19: 6946 | G19: 0 | H19: 0 | I19: 0 | J19: 0 | K19: 0
B20: Accounts Payable | C20: 6844 | D20: 5578 | E20: 5578 | F20: 5633 | G20: ='Working Capital'!G23 -> 4802.1918 | H20: ='Working Capital'!H23 -> 4656.1644 | I20: ='Working Capital'!I23 -> 4615.8904 | J20: ='Working Capital'!J23 -> 4711.9178 | K20: ='Working Capital'!K23 -> 4850.9589
B21: Accrued & Other Current Liab. | C21: 19703 | D21: 20413 | E21: 28289 | F21: 30416 | G21: ='Working Capital'!G24 -> 28170 | H21: ='Working Capital'!H24 -> 26574 | I21: ='Working Capital'!I24 -> 25584 | J21: ='Working Capital'!J24 -> 25960 | K21: ='Working Capital'!K24 -> 26559
B22: Total Current Liabilities | C22: =C19+C20+C21 -> 28788 | D22: =D19+D20+D21 -> 28936 | E22: =E19+E20+E21 -> 44217 | F22: =F19+F20+F21 -> 42995 | G22: =G19+G20+G21 -> 32972.192 | H22: =H19+H20+H21 -> 31230.164 | I22: =I19+I20+I21 -> 30199.89 | J22: =J19+J20+J21 -> 30671.918 | K22: =K19+K20+K21 -> 31409.959
B23: Long-term Debt | C23: 36195 | D23: 32884 | E23: 61538 | F23: 57405 | G23: ='Debt Schedule'!G10 -> 54405 | H23: ='Debt Schedule'!H10 -> 51405 | I23: ='Debt Schedule'!I10 -> 51405 | J23: ='Debt Schedule'!J10 -> 47405 | K23: ='Debt Schedule'!K10 -> 47405
B24: Other Non-current Liabilities | C24: 39030 | D24: 39468 | E24: 31458 | F24: 24499 | G24: =F24 -> 24499 | H24: =G24 -> 24499 | I24: =H24 -> 24499 | J24: =I24 -> 24499 | K24: =J24 -> 24499
B25: Total Liabilities | C25: =C22+C23+C24 -> 104013 | D25: =D22+D23+D24 -> 101288 | E25: =E22+E23+E24 -> 137213 | F25: =F22+F23+F24 -> 124899 | G25: =G22+G23+G24 -> 111876.19 | H25: =H22+H23+H24 -> 107134.16 | I25: =I22+I23+I24 -> 106103.89 | J25: =J22+J23+J24 -> 102575.92 | K25: =K22+K23+K24 -> 103313.96
B26: EQUITY
B27: Total Stockholders' Equity | C27: 77462 | D27: 95916 | E27: 89288 | F27: 88497 | G27: =F27+'Income Statement'!G25-Assumptions!G36*Assumptions!G37-Assumptions!G38 -> 85290.178 | H27: =G27+'Income Statement'!H25-Assumptions!H36*Assumptions!H37-Assumptions!H38 -> 83090.151 | I27: =H27+'Income Statement'!I25-Assumptions!I36*Assumptions!I37-Assumptions!I38 -> 82037.296 | J27: =I27+'Income Statement'!J25-Assumptions!J36*Assumptions!J37-Assumptions!J38 -> 82780.972 | K27: =J27+'Income Statement'!K25-Assumptions!K36*Assumptions!K37-Assumptions!K38 -> 85403.797
B28: Total Liabilities & Equity | C28: =C25+C27 -> 181475 | D28: =D25+D27 -> 197204 | E28: =E25+E27 -> 226501 | F28: =F25+F27 -> 213396 | G28: =G25+G27 -> 197166.37 | H28: =H25+H27 -> 190224.32 | I28: =I25+I27 -> 188141.19 | J28: =J25+J27 -> 185356.89 | K28: =K25+K27 -> 188717.76
B30: Balance Check (TA - TL&E) | C30: =C17-C28 -> 0 | D30: =D17-D28 -> 0 | E30: =E17-E28 -> 0 | F30: =F17-F28 -> 0 | G30: =G17-G28 -> 0 | H30: =H17-H28 -> 0 | I30: =I17-I28 -> 0 | J30: =J17-J28 -> 0 | K30: =K17-K28 -> 0

Sheet Cash Flow Statement
B2: Pfizer Inc. — Cash Flow Statement
B3: ($ in millions)
C5: FY2021 | D5: FY2022 | E5: FY2023 | F5: FY2024 | G5: FY2025E | H5: FY2026E | I5: FY2027E | J5: FY2028E | K5: FY2029E
B7: OPERATING ACTIVITIES
B8: Net Income | C8: 21979 | D8: 31372 | E8: 2119 | F8: 8062 | G8: ='Income Statement'!G25 -> 6369.1779 | H8: ='Income Statement'!H25 -> 7603.9729 | I8: ='Income Statement'!I25 -> 8979.1454 | J8: ='Income Statement'!J25 -> 11003.675 | K8: ='Income Statement'!K25 -> 13110.825
B9: Depreciation | C9: 1491 | D9: 1455 | E9: 1539 | F9: 1727 | G9: =Assumptions!G33 -> 1800 | H9: =Assumptions!H33 -> 1850 | I9: =Assumptions!I33 -> 1900 | J9: =Assumptions!J33 -> 1950 | K9: =Assumptions!K33 -> 2000
B10: Amortization of Intangibles | C10: 3700 | D10: 3609 | E10: 4751 | F10: 5286 | G10: =Assumptions!G19 -> 5000 | H10: =Assumptions!H19 -> 4800 | I10: =Assumptions!I19 -> 4600 | J10: =Assumptions!J19 -> 4400 | K10: =Assumptions!K19 -> 4200
B11: Stock-based Compensation | C11: 616 | D11: 536 | E11: 714 | F11: 877 | G11: 900 | H11: 900 | I11: 900 | J11: 900 | K11: 900
B12: Change in Working Capital | C12: -1934 | D12: -2454 | E12: -1047 | F12: -3066 | G12: =-'Working Capital'!G28 -> 752.30137 | H12: =-'Working Capital'!H28 -> -482.09589 | I12: =-'Working Capital'!I28 -> -352.06849 | J12: =-'Working Capital'!J28 -> 13.573973 | K12: =-'Working Capital'!K28 -> 117.91233
B13: Other Operating Adjustments | C13: 6728 | D13: -5231 | E13: 624 | F13: -142 | G13: 0 | H13: 0 | I13: 0 | J13: 0 | K13: 0
B14: Cash from Operations | C14: =SUM(C8:C13) -> 32580 | D14: =SUM(D8:D13) -> 29287 | E14: =SUM(E8:E13) -> 8700 | F14: =SUM(F8:F13) -> 12744 | G14: =SUM(G8:G13) -> 14821.479 | H14: =SUM(H8:H13) -> 14671.877 | I14: =SUM(I8:I13) -> 16027.077 | J14: =SUM(J8:J13) -> 18267.249 | K14: =SUM(K8:K13) -> 20328.738
B16: INVESTING ACTIVITIES
B17: Capital Expenditures | C17: -2711 | D17: -3236 | E17: -3907 | F17: -2909 | G17: =-'Income Statement'!G7*Assumptions!G32 -> -2817 | H17: =-'Income Statement'!H7*Assumptions!H32 -> -2657.4 | I17: =-'Income Statement'!I7*Assumptions!I32 -> -2620.8 | J17: =-'Income Statement'!J7*Assumptions!J32 -> -2596 | K17: =-'Income Statement'!K7*Assumptions!K32 -> -2587.8
B18: Cash from Investing | C18: =C17 -> -2711 | D18: =D17 -> -3236 | E18: =E17 -> -3907 | F18: =F17 -> -2909 | G18: =G17 -> -2817 | H18: =H17 -> -2657.4 | I18: =I17 -> -2620.8 | J18: =J17 -> -2596 | K18: =K17 -> -2587.8
B20: FINANCING ACTIVITIES
B21: Dividends Paid | C21: -8635 | D21: -9177 | E21: -9364 | F21: -9512 | G21: =-Assumptions!G36*Assumptions!G37 -> -9576 | H21: =-Assumptions!H36*Assumptions!H37 -> -9804 | I21: =-Assumptions!I36*Assumptions!I37 -> -10032 | J21: =-Assumptions!J36*Assumptions!J37 -> -10260 | K21: =-Assumptions!K36*Assumptions!K37 -> -10488
B22: Share Repurchases | C22: -2114 | D22: -3283 | E22: -2000 | F22: 0 | G22: =-Assumptions!G38 -> 0 | H22: =-Assumptions!H38 -> 0 | I22: =-Assumptions!I38 -> 0 | J22: =-Assumptions!J38 -> 0 | K22: =-Assumptions!K38 -> 0
B23: Debt Repayment | C23: -1020 | D23: -5284 | E23: 38729 | F23: -7159 | G23: ='Debt Schedule'!G9 -> -3000 | H23: ='Debt Schedule'!H9 -> -3000 | I23: ='Debt Schedule'!I9 -> 0 | J23: ='Debt Schedule'!J9 -> -4000 | K23: ='Debt Schedule'!K9 -> 0
B24: Cash from Financing | C24: =C21+C22+C23 -> -11769 | D24: =D21+D22+D23 -> -17744 | E24: =E21+E22+E23 -> 27365 | F24: =F21+F22+F23 -> -16671 | G24: =G21+G22+G23 -> -12576 | H24: =H21+H22+H23 -> -12804 | I24: =I21+I22+I23 -> -10032 | J24: =J21+J22+J23 -> -14260 | K24: =K21+K22+K23 -> -10488
B26: Net Change in Cash | C26: =C14+C18+C24 -> 18100 | D26: =D14+D18+D24 -> 8307 | E26: =E14+E18+E24 -> 32158 | F26: =F14+F18+F24 -> -6836 | G26: =G14+G18+G24 -> -571.52071 | H26: =H14+H18+H24 -> -789.52297 | I26: =I14+I18+I24 -> 3374.2769 | J26: =J14+J18+J24 -> 1411.2494 | K26: =K14+K18+K24 -> 7252.9378
B27: Beginning Cash & STI | C27: 10721 | D27: 31069 | E27: 22732 | F27: 12690 | G27: =F28 -> 5854 | H27: =G28 -> 5282.4793 | I27: =H28 -> 4492.9563 | J27: =I28 -> 7867.2333 | K27: =J28 -> 9278.4827
B28: Ending Cash & STI | C28: =C27+C26 -> 28821 | D28: =D27+D26 -> 39376 | E28: =E27+E26 -> 54890 | F28: =F27+F26 -> 5854 | G28: =G27+G26 -> 5282.4793 | H28: =H27+H26 -> 4492.9563 | I28: =I27+I26 -> 7867.2333 | J28: =J27+J26 -> 9278.4827 | K28: =K27+K26 -> 16531.42

Sheet Working Capital
B2: Pfizer Inc. — Working Capital Schedule
B3: ($ in millions)
C5: FY2021 | D5: FY2022 | E5: FY2023 | F5: FY2024 | G5: FY2025E | H5: FY2026E | I5: FY2027E | J5: FY2028E | K5: FY2029E
B7: WORKING CAPITAL DRIVERS
B8: Revenue (ref) | C8: ='Income Statement'!C7 -> 81288 | D8: ='Income Statement'!D7 -> 100330 | E8: ='Income Statement'!E7 -> 59553 | F8: ='Income Statement'!F7 -> 63627 | G8: ='Income Statement'!G7 -> 62600 | H8: ='Income Statement'!H7 -> 61800 | I8: ='Income Statement'!I7 -> 62400 | J8: ='Income Statement'!J7 -> 64900 | K8: ='Income Statement'!K7 -> 68100
B9: COGS (ref) | C9: =-'Income Statement'!C8 -> 30483 | D9: =-'Income Statement'!D8 -> 34344 | E9: =-'Income Statement'!E8 -> 24954 | F9: =-'Income Statement'!F8 -> 17851 | G9: =-'Income Statement'!G8 -> 17528 | H9: =-'Income Statement'!H8 -> 16995 | I9: =-'Income Statement'!I8 -> 16848 | J9: =-'Income Statement'!J8 -> 17198.5 | K9: =-'Income Statement'!K8 -> 17706
B11: DSO (days) | C11: =Assumptions!C25 -> 52 | D11: =Assumptions!D25 -> 40 | E11: =Assumptions!E25 -> 71 | F11: =Assumptions!F25 -> 66 | G11: =Assumptions!G25 -> 65 | H11: =Assumptions!H25 -> 65 | I11: =Assumptions!I25 -> 65 | J11: =Assumptions!J25 -> 65 | K11: =Assumptions!K25 -> 65
B12: DIO (days) | C12: =Assumptions!C26 -> 108 | D12: =Assumptions!D26 -> 95 | E12: =Assumptions!E26 -> 149 | F12: =Assumptions!F26 -> 222 | G12: =Assumptions!G26 -> 180 | H12: =Assumptions!H26 -> 170 | I12: =Assumptions!I26 -> 160 | J12: =Assumptions!J26 -> 155 | K12: =Assumptions!K26 -> 150
B13: DPO (days) | C13: =Assumptions!C27 -> 82 | D13: =Assumptions!D27 -> 59 | E13: =Assumptions!E27 -> 82 | F13: =Assumptions!F27 -> 115 | G13: =Assumptions!G27 -> 100 | H13: =Assumptions!H27 -> 100 | I13: =Assumptions!I27 -> 100 | J13: =Assumptions!J27 -> 100 | K13: =Assumptions!K27 -> 100
B14: Other Curr. Assets % Rev | C14: =Assumptions!C28 -> 0.057 | D14: =Assumptions!D28 -> 0.061 | E14: =Assumptions!E28 -> 0.105 | F14: =Assumptions!F28 -> 0.119 | G14: =Assumptions!G28 -> 0.1 | H14: =Assumptions!H28 -> 0.095 | I14: =Assumptions!I28 -> 0.09 | J14: =Assumptions!J28 -> 0.088 | K14: =Assumptions!K28 -> 0.085
B15: Accrued Liab. % Rev | C15: =Assumptions!C29 -> 0.242 | D15: =Assumptions!D29 -> 0.203 | E15: =Assumptions!E29 -> 0.475 | F15: =Assumptions!F29 -> 0.478 | G15: =Assumptions!G29 -> 0.45 | H15: =Assumptions!H29 -> 0.43 | I15: =Assumptions!I29 -> 0.41 | J15: =Assumptions!J29 -> 0.4 | K15: =Assumptions!K29 -> 0.39
B17: WORKING CAPITAL ITEMS
B18: Accounts Receivable | C18: 11479 | D18: 10952 | E18: 11566 | F18: 11463 | G18: =G8*G11/365 -> 11147.945 | H18: =H8*H11/365 -> 11005.479 | I18: =I8*I11/365 -> 11112.329 | J18: =J8*J11/365 -> 11557.534 | K18: =K8*K11/365 -> 12127.397
B19: Inventories | C19: 9059 | D19: 8981 | E19: 10189 | F19: 10851 | G19: =G9*G12/365 -> 8643.9452 | H19: =H9*H12/365 -> 7915.4795 | I19: =I9*I12/365 -> 7385.4247 | J19: =J9*J12/365 -> 7303.4726 | K19: =K9*K12/365 -> 7276.4384
B20: Other Current Assets | C20: 4654 | D20: 6099 | E20: 6270 | F20: 7567 | G20: =G8*G14 -> 6260 | H20: =H8*H14 -> 5871 | I20: =I8*I14 -> 5616 | J20: =J8*J14 -> 5711.2 | K20: =K8*K14 -> 5788.5
B21: Total Current Assets (ex-Cash) | C21: =C18+C19+C20 -> 25192 | D21: =D18+D19+D20 -> 26032 | E21: =E18+E19+E20 -> 28025 | F21: =F18+F19+F20 -> 29881 | G21: =G18+G19+G20 -> 26051.89 | H21: =H18+H19+H20 -> 24791.959 | I21: =I18+I19+I20 -> 24113.753 | J21: =J18+J19+J20 -> 24572.207 | K21: =K18+K19+K20 -> 25192.336
B23: Accounts Payable | C23: 6844 | D23: 5578 | E23: 5578 | F23: 5633 | G23: =G9*G13/365 -> 4802.1918 | H23: =H9*H13/365 -> 4656.1644 | I23: =I9*I13/365 -> 4615.8904 | J23: =J9*J13/365 -> 4711.9178 | K23: =K9*K13/365 -> 4850.9589
B24: Accrued & Other Current Liab. | C24: 19703 | D24: 20413 | E24: 28289 | F24: 30416 | G24: =G8*G15 -> 28170 | H24: =H8*H15 -> 26574 | I24: =I8*I15 -> 25584 | J24: =J8*J15 -> 25960 | K24: =K8*K15 -> 26559
B25: Total Current Liabilities (ex-Debt) | C25: =C23+C24 -> 26547 | D25: =D23+D24 -> 25991 | E25: =E23+E24 -> 33867 | F25: =F23+F24 -> 36049 | G25: =G23+G24 -> 32972.192 | H25: =H23+H24 -> 31230.164 | I25: =I23+I24 -> 30199.89 | J25: =J23+J24 -> 30671.918 | K25: =K23+K24 -> 31409.959
B27: Net Working Capital | C27: =C21-C25 -> -1355 | D27: =D21-D25 -> 41 | E27: =E21-E25 -> -5842 | F27: =F21-F25 -> -6168 | G27: =G21-G25 -> -6920.3014 | H27: =H21-H25 -> -6438.2055 | I27: =I21-I25 -> -6086.137 | J27: =J21-J25 -> -6099.711 | K27: =K21-K25 -> -6217.6233
B28: Change in NWC | C28: 0 | D28: =D27-C27 -> 1396 | E28: =E27-D27 -> -5883 | F28: =F27-E27 -> -326 | G28: =G27-F27 -> -752.30137 | H28: =H27-G27 -> 482.09589 | I28: =I27-H27 -> 352.06849 | J28: =J27-I27 -> -13.573973 | K28: =K27-J27 -> -117.91233

Sheet Debt Schedule
B2: Pfizer Inc. — Debt Schedule
B3: ($ in millions)
C5: FY2021 | D5: FY2022 | E5: FY2023 | F5: FY2024 | G5: FY2025E | H5: FY2026E | I5: FY2027E | J5: FY2028E | K5: FY2029E
B7: LONG-TERM DEBT
B8: Beginning Balance | G8: =F10 -> 57405 | H8: =G10 -> 54405 | I8: =H10 -> 51405 | J8: =I10 -> 51405 | K8: =J10 -> 47405
B9: Mandatory Repayments | G9: -3000 | H9: -3000 | I9: 0 | J9: -4000 | K9: 0
B10: Ending LT Debt | C10: 36195 | D10: 32884 | E10: 61538 | F10: 57405 | G10: =G8+G9 -> 54405 | H10: =H8+H9 -> 51405 | I10: =I8+I9 -> 51405 | J10: =J8+J9 -> 47405 | K10: =K8+K9 -> 47405
B12: INTEREST CALCULATION
B13: Avg. Debt Balance | G13: =(G8+G10)/2 -> 55905 | H13: =(H8+H10)/2 -> 52905 | I13: =(I8+I10)/2 -> 51405 | J13: =(J8+J10)/2 -> 49405 | K13: =(K8+K10)/2 -> 47405
B14: Interest Expense (negative) | G14: =-G13*G15 -> -2677.8495 | H14: =-H13*H15 -> -2534.1495 | I14: =-I13*I15 -> -2462.2995 | J14: =-J13*J15 -> -2366.4995 | K14: =-K13*K15 -> -2270.6995
B15: Interest Rate (blended) | G15: =Assumptions!C44 -> 0.0479 | H15: =Assumptions!C44 -> 0.0479 | I15: =Assumptions!C44 -> 0.0479 | J15: =Assumptions!C44 -> 0.0479 | K15: =Assumptions!C44 -> 0.0479
B17: MEMO
B18: Total Debt (LT + ST) | C18: 38436 | D18: 35829 | E18: 71888 | F18: 64351 | G18: =G10 -> 54405 | H18: =H10 -> 51405 | I18: =I10 -> 51405 | J18: =J10 -> 47405 | K18: =K10 -> 47405
B19: Net Debt | C19: 7367 | D19: 13097 | E19: 59198 | F19: 43874 | G19: =G18-'Balance Sheet'!G7 -> 49122.521 | H19: =H18-'Balance Sheet'!H7 -> 46912.044 | I19: =I18-'Balance Sheet'!I7 -> 43537.767 | J19: =J18-'Balance Sheet'!J7 -> 38126.517 | K19: =K18-'Balance Sheet'!K7 -> 30873.58

Sheet DCF
B2: Pfizer Inc. — Discounted Cash Flow Analysis
B3: ($ in millions, except per share data)
C5: FY2025E | D5: FY2026E | E5: FY2027E | F5: FY2028E | G5: FY2029E
B7: UNLEVERED FREE CASH FLOW
B8: EBIT | C8: ='Income Statement'!G21 -> 10171 | D8: ='Income Statement'!H21 -> 11480 | E8: ='Income Statement'!I21 -> 13026 | F8: ='Income Statement'!J21 -> 15312 | G8: ='Income Statement'!K21 -> 17695.2
B9: Less: Taxes on EBIT | C9: =-C8*Assumptions!C47 -> -1525.65 | D9: =-D8*Assumptions!C47 -> -1722 | E9: =-E8*Assumptions!C47 -> -1953.9 | F9: =-F8*Assumptions!C47 -> -2296.8 | G9: =-G8*Assumptions!C47 -> -2654.28
B10: NOPAT | C10: =C8+C9 -> 8645.35 | D10: =D8+D9 -> 9758 | E10: =E8+E9 -> 11072.1 | F10: =F8+F9 -> 13015.2 | G10: =G8+G9 -> 15040.92
B11: Plus: D&A | C11: =Assumptions!G33 -> 1800 | D11: =Assumptions!H33 -> 1850 | E11: =Assumptions!I33 -> 1900 | F11: =Assumptions!J33 -> 1950 | G11: =Assumptions!K33 -> 2000
B12: Less: CapEx | C12: =-'Income Statement'!G7*Assumptions!G32 -> -2817 | D12: =-'Income Statement'!H7*Assumptions!H32 -> -2657.4 | E12: =-'Income Statement'!I7*Assumptions!I32 -> -2620.8 | F12: =-'Income Statement'!J7*Assumptions!J32 -> -2596 | G12: =-'Income Statement'!K7*Assumptions!K32 -> -2587.8
B13: Less: Change in NWC | C13: =-'Working Capital'!G28 -> 752.30137 | D13: =-'Working Capital'!H28 -> -482.09589 | E13: =-'Working Capital'!I28 -> -352.06849 | F13: =-'Working Capital'!J28 -> 13.573973 | G13: =-'Working Capital'!K28 -> 117.91233
B14: Unlevered Free Cash Flow (UFCF) | C14: =C10+C11+C12+C13 -> 8380.6514 | D14: =D10+D11+D12+D13 -> 8468.5041 | E14: =E10+E11+E12+E13 -> 9999.2315 | F14: =F10+F11+F12+F13 -> 12382.774 | G14: =G10+G11+G12+G13 -> 14571.032
B16: DISCOUNT FACTORS
B17: WACC | C17: =Assumptions!C54 -> 0.053673289 | D17: =Assumptions!C54 -> 0.053673289 | E17: =Assumptions!C54 -> 0.053673289 | F17: =Assumptions!C54 -> 0.053673289 | G17: =Assumptions!C54 -> 0.053673289
B18: Discount Period | C18: 1 | D18: 2 | E18: 3 | F18: 4 | G18: 5
B19: Discount Factor | C19: =1/(1+C17)^C18 -> 0.94906079 | D19: =1/(1+D17)^D18 -> 0.90071638 | E19: =1/(1+E17)^E18 -> 0.85483459 | F19: =1/(1+F17)^F18 -> 0.81128999 | G19: =1/(1+G17)^G18 -> 0.76996352
B20: PV of UFCF | C20: =C14*C19 -> 7953.7476 | D20: =D14*D19 -> 7627.7203 | E20: =E14*E19 -> 8547.689 | F20: =F14*F19 -> 10046.021 | G20: =G14*G19 -> 11219.163
B22: TERMINAL VALUE
B23: Terminal Year UFCF | C23: =G14 -> 14571.032
B24: Terminal Growth Rate | C24: =Assumptions!C48 -> 0.02
B25: WACC | C25: =Assumptions!C54 -> 0.053673289
B26: Terminal Value (GGM) | C26: =C23*(1+C24)/(C25-C24) -> 441372.18
B27: PV of Terminal Value | C27: =C26*G19 -> 339840.48
B29: VALUATION SUMMARY
B30: Sum of PV of UFCF | C30: =SUM(C20:G20) -> 45394.341
B31: PV of Terminal Value | C31: =C27 -> 339840.48
B32: Enterprise Value | C32: =C30+C31 -> 385234.82
B34: Less: Total Debt (FY2024) | C34: -64351
B35: Plus: Cash & STI (FY2024) | C35: 20477
B36: Equity Value | C36: =C32+C34+C35 -> 341360.82
B37: Diluted Shares (M) | C37: =Assumptions!G37 -> 5700
B38: Implied Share Price | C38: =C36/C37 -> 59.887863
B39: Current Price | C39: 26.6
B40: Upside / (Downside) | C40: =C38/C39-1 -> 1.2514234
B43: SENSITIVITY ANALYSIS — Implied Share Price
C44: Terminal Growth Rate
B45: WACC | C45: 0.01 | D45: 0.015 | E45: 0.02 | F45: 0.025 | G45: 0.03
B46: 0.044 | C46: =(C30+G14*(1+C45)/(B46-C45)*G19+C34+C35)/C37 -> 58.73605 | D46: =(C30+G14*(1+D45)/(B46-D45)*G19+C34+C35)/C37 -> 69.156326 | E46: =(C30+G14*(1+E45)/(B46-E45)*G19+C34+C35)/C37 -> 83.918382 | F46: =(C30+G14*(1+F45)/(B46-F45)*G19+C34+C35)/C37 -> 106.44994 | G46: =(C30+G14*(1+G45)/(B46-G45)*G19+C34+C35)/C37 -> 145.07548
B47: 0.049 | C47: =(C30+G14*(1+C45)/(B47-C45)*G19+C34+C35)/C37 -> 51.239983 | D47: =(C30+G14*(1+D45)/(B47-D45)*G19+C34+C35)/C37 -> 59.025502 | E47: =(C30+G14*(1+E45)/(B47-E45)*G19+C34+C35)/C37 -> 69.495683 | F47: =(C30+G14*(1+F45)/(B47-F45)*G19+C34+C35)/C37 -> 84.32844 | G47: =(C30+G14*(1+G45)/(B47-G45)*G19+C34+C35)/C37 -> 106.96791
B48: 0.054 | C48: =(C30+G14*(1+C45)/(B48-C45)*G19+C34+C35)/C37 -> 45.447567 | D48: =(C30+G14*(1+D45)/(B48-D45)*G19+C34+C35)/C37 -> 51.492326 | E48: =(C30+G14*(1+E45)/(B48-E45)*G19+C34+C35)/C37 -> 59.314954 | F48: =(C30+G14*(1+F45)/(B48-F45)*G19+C34+C35)/C37 -> 69.835041 | G48: =(C30+G14*(1+G45)/(B48-G45)*G19+C34+C35)/C37 -> 84.738497
B49: 0.059 | C49: =(C30+G14*(1+C45)/(B49-C45)*G19+C34+C35)/C37 -> 40.837278 | D49: =(C30+G14*(1+D45)/(B49-D45)*G19+C34+C35)/C37 -> 45.671235 | E49: =(C30+G14*(1+E45)/(B49-E45)*G19+C34+C35)/C37 -> 51.744669 | F49: =(C30+G14*(1+F45)/(B49-F45)*G19+C34+C35)/C37 -> 59.604406 | G49: =(C30+G14*(1+G45)/(B49-G45)*G19+C34+C35)/C37 -> 70.174398
...

Sheet Comps
B2: Pfizer Inc. — Comparable Company Analysis
B3: ($ in billions, as of March 2026)
B5: Company | C5: Ticker | D5: Mkt Cap | E5: EV | F5: LTM Rev | G5: LTM EBITDA | H5: EV/Rev | I5: EV/EBITDA | J5: P/E (NTM) | K5: EBITDA Margin | L5: Div Yield
B6: AbbVie | C6: ABBV | D6: 406.9 | E6: 462 | F6: 56.3 | G6: 29.5 | H6: 8.2 | I6: 15.65 | J6: 15.87 | K6: 0.524 | L6: 0.03
B7: Merck | C7: MRK | D7: 274.3 | E7: 297.5 | F7: 65 | G7: 24.4 | H7: 4.6 | I7: 12.2 | J7: 14.27 | K7: 0.375 | L7: 0.028
B8: Bristol-Myers Squibb | C8: BMY | D8: 113.8 | E8: 147 | F8: 48 | G8: 21.3 | H8: 3.1 | I8: 6.9 | J8: 9.75 | K8: 0.444 | L8: 0.0415
B9: Eli Lilly | C9: LLY | D9: 886.4 | E9: 950.1 | F9: 65.2 | G9: 28.4 | H9: 14.6 | I9: 33.5 | J9: 29.9 | K9: 0.436 | L9: 0.0068
B10: Johnson & Johnson | C10: JNJ | D10: 579.3 | E10: 615.6 | F10: 92.1 | G10: 33.1 | H10: 6.7 | I10: 18.6 | J10: 21.1 | K10: 0.359 | L10: 0.0216
B11: AstraZeneca | C11: AZN | D11: 307.7 | E11: 343.9 | F11: 58.7 | G11: 11.7 | H11: 5.9 | I11: =E11/G11 -> 29.393162 | J11: 22 | K11: =G11/F11 -> 0.19931857 | L11: 0.019
B13: Mean | D13: =AVERAGE(D6:D11) -> 428.06667 | E13: =AVERAGE(E6:E11) -> 469.35 | F13: =AVERAGE(F6:F11) -> 64.216667 | G13: =AVERAGE(G6:G11) -> 24.733333 | H13: =AVERAGE(H6:H11) -> 7.1833333 | I13: =AVERAGE(I6:I11) -> 19.37386 | J13: =AVERAGE(J6:J11) -> 18.815 | K13: =AVERAGE(K6:K11) -> 0.38955309 | L13: =AVERAGE(L6:L11) -> 0.024483333
B14: Median | D14: =MEDIAN(D6:D11) -> 357.3 | E14: =MEDIAN(E6:E11) -> 402.95 | F14: =MEDIAN(F6:F11) -> 61.85 | G14: =MEDIAN(G6:G11) -> 26.4 | H14: =MEDIAN(H6:H11) -> 6.3 | I14: =MEDIAN(I6:I11) -> 17.125 | J14: =MEDIAN(J6:J11) -> 18.485 | K14: =MEDIAN(K6:K11) -> 0.4055 | L14: =MEDIAN(L6:L11) -> 0.0248
B15: Pfizer | C15: PFE | D15: 152.4 | E15: 196.8 | F15: 63.6 | G15: 20.2 | H15: =E15/F15 -> 3.0943396 | I15: =E15/G15 -> 9.7425743 | J15: 18.9 | K15: =G15/F15 -> 0.31761006 | L15: 0.063
B17: IMPLIED VALUATION FROM COMPS
B18: EV/EBITDA (Median) → EV | C18: =I14*G15 -> 345.925
B19: Less: Net Debt | C19: -43.9
B20: Implied Equity Value | C20: =C18+C19 -> 302.025
B21: Shares (B) | C21: 5.7
B22: Implied Price (EV/EBITDA) | C22: =C20/C21 -> 52.986842
B24: P/E (Median NTM) → Price | C24: =J14*'Income Statement'!G28 -> 20.655132

Sheet IS_Raw
B2: Pfizer Inc. — Historical Income Statement
B3: ($ in millions, except per share data)
C5: FY2019 | D5: FY2020 | E5: FY2021 | F5: FY2022 | G5: FY2023 | H5: FY2024
B6: Total Revenue | C6: 41172 | D6: 41908 | E6: 81288 | F6: 100330 | G6: 59553 | H6: 63627
B7: Cost of Sales | C7: -8251 | D7: -8692 | E7: -30483 | F7: -34344 | G7: -24954 | H7: -17851
B8: Gross Profit | C8: 32921 | D8: 33216 | E8: 50467 | F8: 65986 | G8: 34599 | H8: 45776
B10: SI&A Expense | C10: -12750 | D10: -11614 | E10: -12703 | F10: -13554 | G10: -13476 | H10: -14730
B11: R&D Expense | C11: -8394 | D11: -9405 | E11: -10361 | F11: -11428 | G11: -11603 | H11: -10822
B12: Acquired IPR&D | E12: -2627 | F12: -981 | G12: -194 | H12: -108
B13: Amortization of Intangibles | C13: -4462 | D13: -4370 | E13: -3700 | F13: -3609 | G13: -4751 | H13: -5286
B14: Restructuring & Acq. Related | C14: -601 | D14: -805 | E14: -417 | F14: -486 | G14: -3610 | H14: -2419
B15: Gain on Consumer Healthcare JV | C15: 8086
B16: Other (Income)/Deductions, net | C16: -3314 | D16: -1135 | E16: -1437 | F16: -2059 | G16: 3225 | H16: -4388
B17: Income Before Tax (Cont. Ops) | C17: 11485 | D17: 5285 | E17: 29222 | F17: 43869 | G17: 4190 | H17: 8023
B18: Income Tax Expense | C18: -618 | D18: -1608 | E18: -1852 | F18: -3737 | G18: 2027 | H18: 28
B19: Effective Tax Rate | C19: 0.054 | D19: 0.304 | E19: 0.063 | F19: 0.085 | G19: -0.484 | H19: -0.004
B20: Net Income (Cont. Ops) | C20: 10738 | D20: 3658 | E20: 21979 | F20: 31372 | G20: 2119 | H20: 8051
B21: Disc. Ops, net of tax | C21: 5318 | D21: 5805 | H21: 11
B22: Net Income attr. to Pfizer | C22: 16273 | D22: 9616 | E22: 21979 | F22: 31372 | G22: 2119 | H22: 8031
B24: Diluted EPS | C24: 2.87 | D24: 1.71 | E24: 3.85 | F24: 5.47 | G24: 0.37 | H24: 1.41
B25: Diluted Shares (M) | C25: 5675 | D25: 5632 | E25: 5708 | F25: 5733 | G25: 5709 | H25: 5700
B27: Gross Margin | C27: =C8/C6 -> 0.79959681 | D27: =D8/D6 -> 0.7925933 | E27: =E8/E6 -> 0.62084194 | F27: =F8/F6 -> 0.65768962 | G27: =G8/G6 -> 0.58097829 | H27: =H8/H6 -> 0.719443
B28: EBITDA | C28: =C6+C7+C10+C11 -> 11777 | D28: =D6+D7+D10+D11 -> 12197 | E28: =E6+E7+E10+E11 -> 27741 | F28: =F6+F7+F10+F11 -> 41004 | G28: =G6+G7+G10+G11 -> 9520 | H28: =H6+H7+H10+H11 -> 20224
B29: EBITDA Margin | C29: =C28/C6 -> 0.28604391 | D29: =D28/D6 -> 0.29104228 | E29: =E28/E6 -> 0.34126808 | F29: =F28/F6 -> 0.40869132 | G29: =G28/G6 -> 0.15985761 | H29: =H28/H6 -> 0.31785248

Sheet BS_Raw
B2: Pfizer Inc. — Historical Balance Sheet
B3: ($ in millions)
C5: FY2019 | D5: FY2020 | E5: FY2021 | F5: FY2022 | G5: FY2023 | H5: FY2024
B6: ASSETS
B7: Cash & Equivalents | C7: 1198 | D7: 1784 | E7: 1944 | F7: 416 | G7: 2853 | H7: 1487
B8: Short-term Investments | C8: 8525 | D8: 10437 | E8: 29125 | F8: 22316 | G8: 9837 | H8: 18990
B9: Accounts Receivable | C9: 6772 | D9: 7913 | E9: 11479 | F9: 10952 | G9: 11566 | H9: 11463
B10: Inventories | C10: 7068 | D10: 8020 | E10: 9059 | F10: 8981 | G10: 10189 | H10: 10851
B11: Other Current Assets | C11: 9240 | D11: 5505 | E11: 4654 | F11: 6099 | G11: 6270 | H11: 7567
B12: Total Current Assets | C12: 32803 | D12: 33659 | E12: 56261 | F12: 48764 | G12: 40715 | H12: 50358
B13: PP&E, net | C13: 12969 | D13: 13116 | E13: 13508 | F13: 14177 | G13: 17693 | H13: 18393
B14: Goodwill | C14: 54062 | D14: 49802 | E14: 49199 | F14: 49180 | G14: 67782 | H14: 68527
B15: Intangible Assets, net | C15: 28076 | D15: 25413 | E15: 23710 | F15: 30455 | G15: 63979 | H15: 55411
B16: Other Non-current Assets | C16: 39684 | D16: 32239 | E16: 28798 | F16: 54629 | G16: 36332 | H16: 20707
B17: Total Assets | C17: 167594 | D17: 154229 | E17: 181476 | F17: 197205 | G17: 226501 | H17: 213396
B19: LIABILITIES
B20: Short-term Debt / Current LTD | C20: 16561 | D20: 2703 | E20: 2241 | F20: 2945 | G20: 10350 | H20: 6946
B21: Accounts Payable | C21: 4402 | D21: 5261 | E21: 6844 | F21: 5578 | G21: 5578 | H21: 5633
B22: Accrued & Other Current Liab. | C22: 16341 | D22: 14851 | E22: 19703 | F22: 20413 | G22: 28289 | H22: 30416
B23: Total Current Liabilities | C23: 37304 | D23: 22815 | E23: 28788 | F23: 28936 | G23: 44217 | H23: 42995
B24: Long-term Debt | C24: 35955 | D24: 37133 | E24: 36195 | F24: 32884 | G24: 61538 | H24: 57405
B25: Other Non-current Liabilities | C25: 30889 | D25: 30808 | E25: 39030 | F25: 39468 | G25: 31458 | H25: 24499
B26: Total Liabilities | C26: 104148 | D26: 90756 | E26: 104013 | F26: 101288 | G26: 137213 | H26: 124899
B28: Total Stockholders' Equity | C28: 63447 | D28: 63473 | E28: 77462 | F28: 95916 | G28: 89288 | H28: 88497
B29: Total Liabilities & Equity | C29: 167594 | D29: 154229 | E29: 181476 | F29: 197205 | G29: 226501 | H29: 213396
B31: Balance Check (TA - TL&E) | C31: =C17-C29 -> 0 | D31: =D17-D29 -> 0 | E31: =E17-E29 -> 0 | F31: =F17-F29 -> 0 | G31: =G17-G29 -> 0 | H31: =H17-H29 -> 0

Sheet CF_Raw
B2: Pfizer Inc. — Historical Cash Flow Statement
B3: ($ in millions)
C5: FY2019 | D5: FY2020 | E5: FY2021 | F5: FY2022 | G5: FY2023 | H5: FY2024
B6: OPERATING ACTIVITIES
B7: Net Income | C7: 16273 | D7: 9616 | E7: 21979 | F7: 31372 | G7: 2119 | H7: 8062
B8: Depreciation & Amortization | C8: 6076 | D8: 4681 | E8: 5191 | F8: 5064 | G8: 6290 | H8: 7013
B9: Stock-based Compensation | C9: 556 | D9: 612 | E9: 616 | F9: 536 | G9: 714 | H9: 877
B10: Deferred Taxes | C10: -6039 | D10: -1221 | E10: -2196 | F10: -4204 | G10: 3168 | H10: -2102
B11: Changes in Working Capital:
B12: Accounts Receivable | C12: 1065 | D12: -955 | E12: -3614 | F12: 621 | G12: -791 | H12: -109
B13: Inventories | C13: -459 | D13: -987 | E13: -1060 | F13: 70 | G13: -1741 | H13: -854
B14: Accounts Payable & Other | C14: -2095 | D14: 3175 | E14: 2740 | F14: -3145 | G14: 1485 | H14: -2103
B15: Total Working Capital Change | C15: -1489 | D15: 1233 | E15: -1934 | F15: -2454 | G15: -1047 | H15: -3066
B16: Other Operating Adjustments | C16: -3074 | D16: -518 | E16: 8924 | F16: -1047 | G16: -2544 | H16: 1858
B17: Cash from Operations | C17: 12303 | D17: 14403 | E17: 32580 | F17: 29267 | G17: 8700 | H17: 12744
B19: INVESTING ACTIVITIES
B20: Capital Expenditures | C20: -1744 | D20: -2226 | E20: -2711 | F20: -3236 | G20: -3907 | H20: -2909
B21: Acquisitions | C21: -10279 | D21: -214 | E21: -2130 | F21: -1368 | G21: -42649 | H21: 0
B22: Other Investing | C22: -1052 | D22: -1831 | E22: -17705 | F22: -11179 | G22: 14278 | H22: 5561
B23: Cash from Investing | C23: -13075 | D23: -4271 | E23: -22546 | F23: -15783 | G23: -32278 | H23: 2652
B25: FINANCING ACTIVITIES
B26: Dividends Paid | C26: -8089 | D26: -8441 | E26: -8635 | F26: -9177 | G26: -9364 | H26: -9512
B27: Share Repurchases | C27: -8861 | D27: -1243 | E27: -2114 | F27: -3283 | G27: -2000 | H27: 0
B28: Debt Issuance / (Repayment), net | C28: 8543 | D28: -2116 | E28: -1020 | F28: -5284 | G28: 38729 | H28: -7159
B29: Other Financing | C29: -277 | D29: -1849 | E29: 1953 | F29: -1090 | G29: -1299 | H29: -469
B30: Cash from Financing | C30: -8684 | D30: -9649 | E30: -9816 | F30: -14834 | G30: 26066 | H30: -17140
B32: Net Change in Cash | C32: 586 | D32: 586 | E32: -36 | F32: -1528 | G32: 2437 | H32: -1810
